def test_div(num1,num2):
    return num1/num2
    pass
"""
    ئەگەردە پروگرامما خاتلىق چىقماي ئىجرا بولسا print(val) چىقدۇ .
    ئەگەر prin قىلىپ چىقاغان val دا خاتالىق چىقىپ قالسا پروگرامما بۇ يەردە ئىجرا بۇلۇشتىن توختاپ قالىدۇ .
    مېنىڭ مەقسىتىم خاتالىق چىقىپ قالسا مەيلى ، ئەمما پۈتۈن پروگرامما ئىجرا بۇلۇشتىن توختاپ قالسا بولمايدۇ .
    يەنى خاتالىق چىققان پروگرامما بىلەن پۈتۈن پروگرامما توختاپ قالمىسۇن دىمەكچى 
"""
try:
    """
        ئەگەر پروگرامما نۇرمال ئىجرا بولسا print نىڭ ئىچدىكى val چىقسۇن ، ۋە ئاستىدىكى print قىلغان ok چىقسۇن
        يەنى try ئاستىدىكى except قا كىرمەي ئاستىكى print قىلغان ok چىقسۇن
    """
    val=test_div(5,0)
    print(val)
except:
    """ئۈستىدىكى try ئىچدىكى جۈملىدە خاتالىق چىقسا  except ئىچىدىكى  print ئىجرا بولسۇن ھەمدە except ئاستىكى print قىلغان ok چىقسۇن"""
    print("پروگرامما ئىجرا بۇلۇشتا نورمالسىزلىق بار")
print("ok")